Workbook

Sheet Coded Passages
A1: Milei Climate Narratives — v4 Coded Passages · Data source for all summary sheets
A2: # | B2: Dimension | C2: Sub-dimension | D2: Dimension (Full) | E2: Sub-code (Full) | F2: Quoted Passage | G2: Analytical Memo | H2: Speech | I2: Date | J2: Venue | K2: Type | L2: Venue Group | M2: Scope
A3: 1 | B3: D1.2 | C3: Climate Skepticism or Dismissal | D3: D1.2 — Public Science & Expertise | E3: Climate Skepticism or Dismissal | F3: [MILEI — Respuesta]: A ver primero no mienta. Yo no niego el cambio climático. Lo que yo digo es que existe en la historia de la tierra un ciclo de temperaturas, es decir hay un comportamiento cíclico y este es el quinto punto del ciclo — donde la diferencia con los cuatro anteriores es que antes no estaba el ser humano. Por lo tanto todas esas políticas que culpan al ser humano del cambio climático son falsas y lo único que buscan es recaudar fondos para financiar vagos socialistas que escriben papers de cuarta. | G3: Milei performs the disclaimer-then-dismiss move: "I don't deny climate change" is immediately followed by the natural-cycles attribution, which reproduces effective denial while maintaining rhetorical deniability. The key claim — "all those policies that blame humans for climate change are false" — is a direct dismissal of the scientific basis for climate regulation, delivered as a logical conclusion from the paleoclimatic premise. This is the most compressed instance of Climate_Skepticism_or_Dismissal in the corpus: denial of anthropogenic attribution without denial of the climate phenomenon itself. | H3: Debate Presidencial 2023 | I3: 2023-10-08 | J3: Buenos Aires | K3: debate presidencial | L3: Ideological & Political Events | M3: National
A4: 2 | B4: D1.1 | C4: Sustainability as Ideological or Harmful | D4: D1.1 — State Intervention & Governance | E4: Sustainability as Ideological or Harmful | F4: [MILEI — Respuesta]: A ver primero no mienta. Yo no niego el cambio climático. Lo que yo digo es que existe en la historia de la tierra un ciclo de temperaturas, es decir hay un comportamiento cíclico y este es el quinto punto del ciclo — donde la diferencia con los cuatro anteriores es que antes no estaba el ser humano. Por lo tanto todas esas políticas que culpan al ser humano del cambio climático son falsas y lo único que buscan es recaudar fondos para financiar vagos socialistas que escriben papers de cuarta. | G4: "Recaudar fondos para financiar vagos socialistas que escriben papers de cuarta" reframes climate policy as a rent-extraction mechanism for a parasitic academic class. The claim is not that climate policy is merely wrong — it is that climate policy exists as an institutional vehicle for redistributing resources to ideologically motivated, low-quality scholarship. This is Sustainability_as_Ideological_or_Harmful at its most direct: the policy's real function is material redistribution under ideological cover, not environmental protection. | H4: Debate Presidencial 2023 | I4: 2023-10-08 | J4: Buenos Aires | K4: debate presidencial | L4: Ideological & Political Events | M4: National
A5: 3 | B5: D1.2 | C5: Attack on Experts & Technocrats | D5: D1.2 — Public Science & Expertise | E5: Attack on Experts & Technocrats | F5: [MILEI — Respuesta]: A ver primero no mienta. Yo no niego el cambio climático. Lo que yo digo es que existe en la historia de la tierra un ciclo de temperaturas, es decir hay un comportamiento cíclico y este es el quinto punto del ciclo — donde la diferencia con los cuatro anteriores es que antes no estaba el ser humano. Por lo tanto todas esas políticas que culpan al ser humano del cambio climático son falsas y lo único que buscan es recaudar fondos para financiar vagos socialistas que escriben papers de cuarta. | G5: "Vagos socialistas que escriben papers de cuarta" is the rawest expert delegitimation in the corpus — climate scientists reduced to lazy, ideologically motivated rent-seekers producing worthless work. Unlike the more sophisticated epistemological arguments deployed at Davos (which grant good intentions while invalidating the theoretical framework), here the attack is purely ad hominem and institutional, characterizing climate science as professionally worthless rather than merely theoretically flawed. | H5: Debate Presidencial 2023 | I5: 2023-10-08 | J5: Buenos Aires | K5: debate presidencial | L5: Ideological & Political Events | M5: National
A6: 4 | B6: D1.3 | C6: Anti-Socialism / Anti-Collectivism | D6: D1.3 — Cultural Backlash | E6: Anti-Socialism / Anti-Collectivism | F6: Nuestras costas recibían con brazos abiertos a millones de inmigrantes que se escapaban de una Europa desbastada en búsqueda de un horizonte de progreso. Lamentablemente nuestra dirigencia decidió abandonar el modelo que nos había hecho ricos, y abrazaron las ideas empobrecedoras del colectivismo. | G6: Explicit naming of "colectivismo" as the impoverishing doctrine that displaced Argentina's liberal founding model. No climate or green-agenda content is present in this passage, but the code's v4 scope was broadened precisely to capture "anti-collectivism framings that do not explicitly invoke Marxism" or an environmental referent — this passage establishes the collectivism-as-decline master narrative that later speeches (Davos, UN) apply specifically to environmentalism and the 2030 Agenda. | H6: Discurso De Asuncion Presidencial | I6: 2023-12-10 | J6: Buenos Aires (Escalinatas Del Congreso) | K6: acto institucional | L6: State & Institutional Acts | M6: National
A7: 5 | B7: D1.1 | C7: Anti-Casta (Elite Frame) | D7: D1.1 — State Intervention & Governance | E7: Anti-Casta (Elite Frame) | F7: Durante más de 100 años los políticos han insistido en defender un modelo que lo único que genera es pobreza, estancamiento y miseria. Un modelo que considera que los ciudadanos estamos para servir a la política y no que la política existe para servir a los ciudadanos; un modelo que considera que la tarea de un político es dirigir la vida de los individuos en todos los ámbitos y esferas posibles; un modelo que considera el Estado como un botín de guerra que hay que repartir entre los amigos. Señores, ese modelo ha fracasado, ha fracasado en todo el mundo, pero en especial ha fracasado en nuestro país. | G7: "El Estado como un botín de guerra que hay que repartir entre los amigos" is the parasites/producers extraction logic at the core of the la-casta frame: governance positions exist to be divided among political allies rather than to serve citizens ("los ciudadanos estamos para servir a la política y no... la política... para servir a los ciudadanos" inverts the proper relationship). No climate or environmental referent is present, but per the v4 scope rule (coding_book_v4.md §2b) this is codeable on its own terms — it is the same extractive-elite mechanism later applied explicitly to environmental agencies and international governance bodies in the Davos and UN speeches, and it is structurally identical to the coded Anti_Casta example in the 2024-03-01 apertura speech ("la casta política es lo peor que le puede pasar a un país"). | H7: Discurso De Asuncion Presidencial | I7: 2023-12-10 | J7: Buenos Aires (Escalinatas Del Congreso) | K7: acto institucional | L7: State & Institutional Acts | M7: National
A8: 6 | B8: D1.1 | C8: Market Primacy | D8: D1.1 — State Intervention & Governance | E8: Market Primacy | F8: En materia social estamos recibiendo un país, donde la mitad es pobre, con el tejido social completamente roto. Así, más de 20 millones de argentinos no pueden vivir una vida digna porque son presos de un sistema, que lo único que genera es más pobreza. Como dice el gran Jesús Huerta de Soto: "los planes contra la pobreza generan más pobreza". La única forma de salir de la pobreza es con más libertad. | G8: The Huerta de Soto citation performs the canonical Market_Primacy move: state anti-poverty intervention is declared categorically counterproductive ("los planes contra la pobreza generan más pobreza"), and freedom/markets are asserted as the only legitimate remedy ("la única forma"). This is the same appeal-to-Austrian-authority pattern used throughout the corpus (e.g., the Davos "evidencia empírica es incuestionable" passage) to foreclose any state-coordinated policy response, including on sustainability, before a specific case is argued.* Al mismo tiempo, 6 millones de chicos – hoy a la noche – se irán a dormir con hambre; algunos caminan descalzos por la calle y otros cayeron en la droga. | H8: Discurso De Asuncion Presidencial | I8: 2023-12-10 | J8: Buenos Aires (Escalinatas Del Congreso) | K8: acto institucional | L8: State & Institutional Acts | M8: National
A9: 7 | B9: D1.1 | C9: Anti-State / Anti-Bureaucratic | D9: D1.1 — State Intervention & Governance | E9: Anti-State / Anti-Bureaucratic | F9: En materia de salud, el sistema se encuentra completamente colapsado, pues los hospitales están destruidos; los médicos cobran una miseria y los argentinos no tienen acceso a salud básica. Tan es así, que - durante la pandemia - si los argentinos hubiéramos hecho las cosas como la media de los países, no hubiéramos tenido 30 mil muertos, pero gracias al "Estado te cuida" y su ineficiencia 130.000 argentinos perdieron la vida. | G9: "Estado te cuida" (a slogan associated with pandemic-era state paternalism) is turned into an indictment of state incompetence, with a mortality figure attached to dramatize the cost of state intervention as such. This is a general public-health example, not an environmental one, but the rhetorical mechanism — attaching a catastrophic body count to "the state protects you" branding — is the same delegitimization move later redirected at sustainability governance and multilateral bodies (e.g., the UN's pandemic-response framing in the 2024 General Assembly speech). | H9: Discurso De Asuncion Presidencial | I9: 2023-12-10 | J9: Buenos Aires (Escalinatas Del Congreso) | K9: acto institucional | L9: State & Institutional Acts | M9: National
A10: 8 | B10: D1.1 | C10: Anti-Casta (Elite Frame) | D10: D1.1 — State Intervention & Governance | E10: Anti-Casta (Elite Frame) | F10: Ese es el Estado presente del que los políticos tanto hablan, argumento que utilizan para justificar el aumento descomunal del gasto público que sólo los beneficia a ellos. En todas las esferas – miren dónde miren – la situación de la Argentina es de emergencia. | G10: "El Estado presente" — the justification political actors invoke for public spending — is reframed as existing "sólo para beneficiarlos a ellos" (only benefiting the political class itself), the parasites/producers logic central to the la-casta frame applied here to the general concept of state presence rather than to any specific sustainability program. | H10: Discurso De Asuncion Presidencial | I10: 2023-12-10 | J10: Buenos Aires (Escalinatas Del Congreso) | K10: acto institucional | L10: State & Institutional Acts | M10: National
A11: 9 | B11: D1.3 | C11: Anti-Socialism / Anti-Collectivism | D11: D1.3 — Cultural Backlash | E11: Anti-Socialism / Anti-Collectivism | F11: Estamos haciendo nuestro máximo esfuerzo para intentar disminuir los efectos trágicos de lo que puede ser la peor crisis de nuestra historia, producto de décadas de gobiernos que han insistido con recetas fracasadas, porque como dijimos durante todos estos meses: "El problema no es el chef, sino la receta". Esas ideas que fracasaron en la Argentina son las mismas ideas que han fracasado a lo largo y a lo ancho del planeta, porque allí donde se intentaron han sido un fracaso económico, han sido un fracaso en lo social, han sido un fracaso en lo cultural, y encima les han costado la vida a millones de seres humanos. Esa doctrina, que algunos podrían llamar izquierda, socialismo, fascismo, comunismo, y que a nosotros nos gusta catalogar como colectivismo, es una forma de pensamiento que diluye al individuo en favor del poder del Estado. Es el fundamento básico del modelo de la casta, es una doctrina de pensamiento que parte de la premisa de que la razón de Estado es más importante que los individuos que componen la Nación; que el individuo solo es reconocido si se somete al Estado, y que, por lo tanto, los ciudadanos le debemos pleitesía a sus representantes, la casta política. Es decir, que los individuos no son sino un medio para los fines del Estado; es una forma de ver el mundo que consiste en la creencia de que un grupo de hombres, los políticos, son superiores al resto de los individuos y que por lo tanto deben ser ellos quienes rijan los destinos de sus compatriotas. Una doctrina que parte de la idea de que un grupo de burócratas, sentados en una oficina, pueden planificar la vida de millones de seres humanos, considerando sus deseos, capacidades, preferencias y circunstancias. Es una doctrina que considera que los políticos, en consecuencia, son omnipresentes, omniscientes y omnipotentes, es decir, que en esencia es una doctrina que considera que los políticos son Dios. | G11: This is the fullest doctrinal elaboration of "colectivismo" in the corpus so far: Milei explicitly names and defines the doctrine ("izquierda, socialismo, fascismo, comunismo... colectivismo") as one that "diluye al individuo en favor del poder del Estado," and derives the la-casta model and the omnipotent-bureaucrat imagery as downstream consequences of that doctrine ("es el fundamento básico del modelo de la casta"). Anti_Socialism_Anti_Collectivism is the dominant code rather than Anti_Casta or Anti_State_Anti_Bureaucratic because the paragraph's own structure presents collectivism as the root and casta/bureaucracy as its expressions — removing the collectivism framing would collapse the passage's core argument, whereas removing the casta/bureaucrat imagery would not (per the overcoding test in Rule 2). No climate content is present, but per the v4 scope rule this foundational doctrine-critique is codeable on its own terms — it is the same "colectivismo" frame later applied explicitly to environmentalism at Davos ("los socialistas... el hombre contra la naturaleza") and the UN ("2030 Agenda... socialist in nature"). | H11: Anuncios Por Cadena Nacional (Dnu/Desregulacion) | I11: 2023-12-20 | J11: Buenos Aires (Salon Blanco) | K11: cadena nacional | L11: State & Institutional Acts | M11: National
A12: 10 | B12: D1.1 | C12: Anti-Casta (Elite Frame) | D12: D1.1 — State Intervention & Governance | E12: Anti-Casta (Elite Frame) | F12: Pues bien, nosotros hemos venido a decirles que los políticos no solo no son Dios, sino que son la causa de nuestros problemas. Son la causa de nuestros problemas porque durante décadas han defendido estas ideas empobrecedoras de las que hablamos, mientras ellos se hacían cada vez más ricos; porque es la implementación inclemente de estas ideas por más de 100 años, lo que nos llevó poco a poco, peldaño por peldaño, al infierno económico que vivimos hoy. | G12: "Mientras ellos se hacían cada vez más ricos" is the parasites/producers distinction at the heart of Anti_Casta: the political class personally enriched itself while advocating impoverishing doctrine on behalf of "the people." This is the same extractive-elite mechanism coded in the 2024-03-01 benchmark ("la casta política es lo peor que le puede pasar a un país"), applied here to the same general political class rather than to a sustainability-specific institution — codeable under the v4 scope rule regardless. | H12: Anuncios Por Cadena Nacional (Dnu/Desregulacion) | I12: 2023-12-20 | J12: Buenos Aires (Salon Blanco) | K12: cadena nacional | L12: State & Institutional Acts | M12: National
A13: 11 | B13: D1.1 | C13: Anti-State / Anti-Bureaucratic | D13: D1.1 — State Intervention & Governance | E13: Anti-State / Anti-Bureaucratic | F13: Un aspecto central del fracaso de los últimos 100 años es la injerencia que el Estado ha tenido en la vida de los ciudadanos, de esa creencia de que los políticos son seres superiores que deben regir los destinos de cada uno de nosotros, se desprende un andamiaje institucional que hace que nadie pueda trabajar, comerciar, circular o educarse sin el permiso de ellos; mientras que en una sociedad libre todo está permitido, salvo lo que está prohibido. En una sociedad colectivista como en la Argentina, todo está prohibido, salvo lo que está permitido por los políticos. | G13: The permission-based-society framing ("nadie pueda trabajar, comerciar, circular o educarse sin el permiso de ellos") is the bureaucratic-gatekeeping variant of Anti_State_Anti_Bureaucratic — the state apparatus as a universal permission-granting authority rather than a rights-protecting one. The inverted-freedom formula ("todo está prohibido, salvo lo que está permitido") is a general regulatory-state critique, not an environmental one, but it is the same permission-apparatus logic later applied to environmental permitting and monitoring regimes elsewhere in the corpus. | H13: Anuncios Por Cadena Nacional (Dnu/Desregulacion) | I13: 2023-12-20 | J13: Buenos Aires (Salon Blanco) | K13: cadena nacional | L13: State & Institutional Acts | M13: National
A14: 12 | B14: D1.1 | C14: Delegitimization of Regulation | D14: D1.1 — State Intervention & Governance | E14: Delegitimization of Regulation | F14: Para solucionar los problemas que causan los distintos políticos que intentan financiar el déficit en vez de afrontar la causa, que es el déficit fiscal los políticos introducen regulaciones, controles de precios, cepos, trabas burocráticas y normativas, que violan la libertad y el derecho de propiedad de los argentinos, entorpece el cálculo económico y destruye la generación de riqueza. | G14: Regulations, price controls, and "trabas burocráticas" are cast as categorically illegitimate — violations of liberty and property rather than policy tools with tradeoffs — and blamed for destroying "el cálculo económico," echoing the Austrian economic-calculation argument used elsewhere in the corpus against environmental regulation specifically (e.g., the Davos neoclassical-externality-theory passage). Here the target is general economic regulation (price controls, "cepos"), not environmental regulation, but the delegitimizing mechanism — regulation as coercive rights violation — is identical. | H14: Anuncios Por Cadena Nacional (Dnu/Desregulacion) | I14: 2023-12-20 | J14: Buenos Aires (Salon Blanco) | K14: cadena nacional | L14: State & Institutional Acts | M14: National
... A615: 613 | B615: D1.3 | C615: Anti-Socialism / Anti-Collectivism | D615: D1.3 — Cultural Backlash | E615: Anti-Socialism / Anti-Collectivism | F615: Todas esas políticas fracasaron todas, ninguna funcionó. Por lo tanto, entendamos que estamos en una situación de mucho progreso tecnológico, en cambio de precios relativos, en gran desregulación, en que se corre el Estado del medio. Los precios relativos van a cambiar y los recursos se van a reasignar. Lo que necesitamos es que haya la mayor flexibilidad posible, para que las reasignaciones de recursos sean lo más rápido posible. Si aceptamos este desafío, que es el desafío del cambio, volveremos a ser grandes nuevamente. Si no tenemos los cojones para enfrentar el cambio, nos vamos a convertir en la mierda que nos llevaba el kirchnerismo. | G615: The speech's closing warning names "kirchnerismo" — Milei's standing label for domestic "socialismo del siglo XXI" (cf. the 2026-03-14 Madrid coding) — as the default fate awaiting Argentina should it fail to embrace the deregulatory transition just described. This is a discrete rhetorical move (the concluding stakes-setting device) rather than elaboration of the growth-theory content preceding it. | H615: Cierre De La Expo Efi 2026 | I615: 2026-04-29 | J615: Buenos Aires (C. De Convenciones) | K615: foro economico | L615: Economic & Business Forums | M615: National

Sheet Freq — By Dimension
A1: Dimension Totals — values update automatically from 'Coded Passages'
A2: Dimension | B2: Dimension (Full) | C2: Total | D2: % of Corpus
A3: D1.1 | B3: D1.1 — State Intervention & Governance | C3: =COUNTIFS('Coded Passages'!$B:$B,$A3) -> 377 | D3: =C3/$C$7 -> 0.61500816
A4: D1.2 | B4: D1.2 — Public Science & Expertise | C4: =COUNTIFS('Coded Passages'!$B:$B,$A4) -> 66 | D4: =C4/$C$7 -> 0.10766721
A5: D1.3 | B5: D1.3 — Cultural Backlash | C5: =COUNTIFS('Coded Passages'!$B:$B,$A5) -> 170 | D5: =C5/$C$7 -> 0.27732463
A6: IND | B6: Inductive | C6: =COUNTIFS('Coded Passages'!$B:$B,$A6) -> 0 | D6: =C6/$C$7 -> 0
A7: TOTAL | B7: All Dimensions | C7: =SUM(C3:C6) -> 613 | D7: =SUM(D3:D6) -> 1

Sheet Freq — By Sub-code
A1: Code Frequency by Sub-code × Speech — values update automatically from 'Coded Passages'
A2: Dim | B2: Sub-code | C2: Debate Presidencial 2023 | D2: Discurso De Asuncion Presidencial | E2: Anuncios Por Cadena Nacional (Dnu/Desregulacion) | F2: Mensaje De Fin De Año Al Pueblo Argentino | G2: 54A Reunion Anual Del Foro Economico Mundial (Davos) | H2: Conferencia De Accion Politica Conservadora (Cpac) | I2: Apertura Del 142 Periodo De Sesiones Ordinarias | J2: Apertura Del Ciclo Lectivo | K2: Foro Economico De Las Americas (Iefa Latam Forum) | L2: 42 Aniversario Del Dia Del Veterano Y De Los Caidos En Malvinas | M2: Palabras Junto A La Gral. Laura Richardson (Southcom) | N2: Foro Llao Llao | O2: Cadena Nacional (Equilibrio Fiscal) | P2: Cena Anual De La Fundacion Libertad | Q2: Consejo Interamericano De Comercio Y Produccion (Cicyp) | R2: Presentacion Del Libro *El Camino Del Libertario* | S2: Acto De Vox "Viva 24" | T2: Cierre Del Congreso Del Iaef (Ejecutivos De Finanzas) | U2: Presentacion De Su Libro | V2: Cadena Nacional – 214 Aniversario Revolucion De Mayo | W2: Clase Abierta En El Instituto Hoover (Universidad De Stanford) | X2: 10 Latam Economic Forum | Y2: 30A Edicion De Agroactiva 2024 | Z2: Conferencia Del Instituto Cato Y Libertad Y Progreso | AA2: Expofi 2024 | AB2: Acto Del Dia De La Bandera | AC2: Medalla Internacional De La Comunidad De Madrid | AD2: Premio Juan De Mariana 2024 | AE2: Premio De La Sociedad Hayek | AF2: Premio Del Instituto Liberal De La Republica Checa | AG2: Presentacion Del Plan Nacional De Alfabetizacion | AH2: Cpac Brasil | AI2: Firma Del Pacto De Mayo | AJ2: 172 Aniversario De La Bolsa De Comercio De Buenos Aires | AK2: Premio A La Investigacion Politica (Fundacion Ilan) | AL2: Exposicion De Ganaderia, Agricultura E Industria Internacional | AM2: Acto Por 1Er Trillon De Pies³ De Gas – Gasoducto Gas Andes | AN2: 21A Conferencia Anual Del Council Of The Americas | AO2: Congreso De Inversiones Inmobiliarias | AP2: Cena De Camaraderia De Las Fuerzas Armadas | AQ2: 140 Aniversario De La Bolsa De Comercio De Rosario | AR2: Dia De La Industria – Union Industrial Argentina | AS2: Visita A Mercado Libre | AT2: Foro Madrid – Edicion Rio De La Plata | AU2: Convencion Anual Del Iaef | AV2: Cadena Nacional – Presentacion Del Presupuesto 2025 | AW2: Palabras Ante Inversores En La Bolsa De Nueva York | AX2: 79 Asamblea General De La Onu – Debate General | AY2: Xxxv Asamblea Plenaria Del Consejo Empresarial De America Latina (Ceal) | AZ2: Presentacion Del Centro Cultural Palacio Libertad (Ex Cck) | BA2: Jornadas Monetarias Y Bancarias 2024 (Bcra) | BB2: 60 Coloquio De Idea 2024 | BC2: Tech Forum Argentina 2024 | BD2: Evento Del Foro Economico Mundial (Wef) En Buenos Aires | BE2: Ieral (Fundacion Mediterranea) | BF2: Escuela De Cadetes "Comisario Gral. Juan A. Pirker" – Entrega De Premios | BG2: 100 Aniversario De La Camara Argentina De Comercio Y Servicios | BH2: Visita A La Sede Corporativa De Uala | BI2: Gala Anual De La Fundacion Endeavor | BJ2: Meta Day Argentina | BK2: Cena De La Fundacion Faro | BL2: Gala Del America First Policy Institute | BM2: Palabras Ante Inversores De La Cpac | BN2: Cumbre De Lideres Del G20 – Intervencion | BO2: Cumbre De Lideres Del G20 – Sesion Ii | BP2: Declaracion Conjunta Con Giorgia Meloni (Italia) | BQ2: Encuentro Empresarial Argentina–Israel | BR2: Entrega De Sables A Las Fuerzas De Seguridad | BS2: Apertura De La Semana De La Inteligencia Artificial | BT2: Conferencia Politica De Accion Conservadora (Cpac Argentina) | BU2: Encuentro De Los Lideres (El Cronista) | BV2: Inauguracion Del Centro Comercial Coto | BW2: Lxv Cumbre Del Mercosur | BX2: Asuncion De La Presidencia Pro-Tempore Del Mercosur | BY2: Reconocimiento De La Asociacion De Dirigentes De Marketing | BZ2: Cadena Nacional – Primer Año De Gestion | CA2: Premio Internacional "Milton Friedman" | CB2: Entrega De Sables Y Medallas En Egreso De Oficiales De Las Tres Fuerzas Militares | CC2: Inauguracion De La Nueva Sede De La Bolsa De Comercio De Cordoba | CD2: Cena Anual De La Fundacion Federalismo Y Libertad | CE2: Anuncios En Materia Nuclear (Plan Nuclear Argentino) | CF2: Gala Inaugural Hispanica – Premio Lws "Titan De La Reforma Economica" | CG2: Gala 1775 – Premio "Campeon De La Libertad Economica" | CH2: Milken Center | CI2: Foro Economico Mundial De Davos 2025 | CJ2: Premio Röpke Del Liberal Institut | CK2: Banco Interamericano De Desarrollo (Bid) | CL2: Cpac Washington 2025 | CM2: Apertura Del 143 Periodo De Sesiones Ordinarias | CN2: Expoagro 2025 | CO2: Homenaje A Los Heroes De Malvinas | CP2: Declaracion Conjunta (Visita Oficial) | CQ2: Cadena Nacional – "Fin Del Cepo" | CR2: Declaracion Conjunta Con Scott Bessent (Tesoro Ee.Uu.) | CS2: Condecoracion Orden De Mayo Al Dr. Jesus Huerta De Soto | CT2: Expoefi Argentina 2025 | CU2: 11A Edicion Del Latam Economic Forum 2025 | CV2: 42 Congreso Anual Del Iaef | CW2: Amcham Summit 2025 | CX2: Madrid Economic Forum | CY2: Discurso En La Kneset (Parlamento De Israel) | CZ2: Clase Magistral En La Universidad Hebrea De Jerusalen | DA2: Memorando De La Democracia Y La Libertad (Con Netanyahu) | DB2: Premio Escuela De Salamanca | DC2: Presentacion Del Departamento Federal De Investigaciones (Dfi) | DD2: Acto De Juramento Por El Dia De La Bandera | DE2: Evento De La Libertad Avanza | DF2: Lxvi Cumbre Del Mercosur | DG2: Inauguracion De La Iglesia "Portal Del Cielo" | DH2: Balance De La Desregulacion Con Facultades Delegadas | DI2: 171 Aniversario De La Bolsa De Comercio De Buenos Aires | DJ2: Jockey Club Buenos Aires | DK2: La Derecha Fest | DL2: 137A Inauguracion De La Exposicion De La Rural | DM2: "Voceros De La Libertad" – Fundacion Faro | DN2: Cadena Nacional – Deficit Cero Y Politica Monetaria | DO2: Liberty International World Conference | DP2: Council Of The Americas 2025 | DQ2: 141 Aniversario De La Bolsa De Comercio De Rosario | DR2: Inauguracion Del Nuevo Edificio De Corporacion America | DS2: Consejo Interamericano De Comercio Y Produccion (Cicyp) 2025 | DT2: Palabras Ante Lideres Empresariales Milken Institute | DU2: Europa Viva 25 (Vox) | DV2: Cpac Paraguay 2025 | DW2: Foro De Emprendedores Industriales Del Paraguay | DX2: Cadena Nacional – Presupuesto Nacional 2026 | DY2: Bolsa De Comercio De Cordoba | DZ2: 80 Asamblea General De La Onu | EA2: Premio "Global Citizen 2025" (Atlantic Council) | EB2: Inauguracion De La Feria Internacional De Turismo (Fit) | EC2: Presentacion Del Libro *Cambia La Musica* (S. Di Stefano) | ED2: Presentacion Reformas "Tolerancia Cero Con El Crimen" | EE2: Inauguracion De La Fabrica De Lamb Weston | EF2: Camara De Comercio, Industria Y Agropecuaria De San Rafael - Almuerzo De Las Fuerzas Vivas | EG2: Fabrica Sidersa – Plan "Argentina Grande Otra Vez" | EH2: Encuentro Organizado Por Jp Morgan | EI2: America Business Forum | EJ2: Cena De Gala Del Cpac | EK2: 12 Congreso De Economia Regional Del Club De La Libertad | EL2: Corporacion America | EM2: 90 Aniversario De La Daia | EN2: Encuentro De Lideres De El Cronista | EO2: Presentacion De La Flota F-16 | EP2: Cena De Fin De Año De La Fundacion Faro | EQ2: Entrega De Sables Y Medallas (Egreso Ff.Aa.) | ER2: Cumbre De Jefes De Estado Del Mercosur | ES2: Ceremonia De Firma Del Acuerdo Mercosur–Union Europea | ET2: Foro Economico Mundial De Davos 2026 | EU2: Derecha Fest | EV2: 213 Aniversario Del Combate De San Lorenzo | EW2: Apertura Del 144 Periodo De Sesiones Ordinarias | EX2: Visita Al Centro De Monitoreo De Visa Argentina | EY2: Gala Anual J100 De The Algemeiner | EZ2: Inauguracion Del Argentina Week 2026 | FA2: Yeshiva University | FB2: Madrid Economic Forum 2026 | FC2: Homenaje A Adam Smith | FD2: Foro Economico Del Noa 2026 | FE2: Cpac Budapest | FF2: Doctorado Honoris Causa – Universidad Ludovika | FG2: Cadena Nacional – Fallo Favorable Por Ypf | FH2: Visita Al Centro De Formacion De Capital Humano | FI2: Amcham Summit 2026 | FJ2: Presentacion Ruta Aerea Ba–Tel Aviv (Conf. Con Netanyahu) | FK2: Doctorado Honoris Causa – Universidad Bar-Ilan | FL2: Palabras Junto A Isaac Herzog | FM2: Cena Anual 2026 De La Fundacion Libertad | FN2: Debate "Keynes Y La Teoria General" | FO2: Cierre De La Expo Efi 2026 | FP2: TOTAL
A3: D1.1 | B3: Anti-Casta (Elite Frame) | C3: =COUNTIFS('Coded Passages'!$B:$B,$A3,'Coded Passages'!$E:$E,$B3,'Coded Passages'!$H:$H,C$2) -> 0 | D3: =COUNTIFS('Coded Passages'!$B:$B,$A3,'Coded Passages'!$E:$E,$B3,'Coded Passages'!$H:$H,D$2) -> 2 | E3: =COUNTIFS('Coded Passages'!$B:$B,$A3,'Coded Passages'!$E:$E,$B3,'Coded Passages'!$H:$H,E$2) -> 2 | F3: =COUNTIFS('Coded Passages'!$B:$B,$A3,'Coded Passages'!$E:$E,$B3,'Coded Passages'!$H:$H,F$2) -> 1 | G3: =COUNTIFS('Coded Passages'!$B:$B,$A3,'Coded Passages'!$E:$E,$B3,'Coded Passages'!$H:$H,G$2) -> 2 | H3: =COUNTIFS('Coded Passages'!$B:$B,$A3,'Coded Passages'!$E:$E,$B3,'Coded Passages'!$H:$H,H$2) -> 1 | I3: =COUNTIFS('Coded Passages'!$B:$B,$A3,'Coded Passages'!$E:$E,$B3,'Coded Passages'!$H:$H,I$2) -> 1 | J3: =COUNTIFS('Coded Passages'!$B:$B,$A3,'Coded Passages'!$E:$E,$B3,'Coded Passages'!$H:$H,J$2) -> 0 | ... FO3: =COUNTIFS('Coded Passages'!$B:$B,$A3,'Coded Passages'!$E:$E,$B3,'Coded Passages'!$H:$H,FO$2) -> 1 | FP3: =SUM(C3:FO3) -> 116
A4: D1.3 | B4: Anti-Socialism / Anti-Collectivism | C4: =COUNTIFS('Coded Passages'!$B:$B,$A4,'Coded Passages'!$E:$E,$B4,'Coded Passages'!$H:$H,C$2) -> 0 | D4: =COUNTIFS('Coded Passages'!$B:$B,$A4,'Coded Passages'!$E:$E,$B4,'Coded Passages'!$H:$H,D$2) -> 1 | E4: =COUNTIFS('Coded Passages'!$B:$B,$A4,'Coded Passages'!$E:$E,$B4,'Coded Passages'!$H:$H,E$2) -> 1 | F4: =COUNTIFS('Coded Passages'!$B:$B,$A4,'Coded Passages'!$E:$E,$B4,'Coded Passages'!$H:$H,F$2) -> 1 | G4: =COUNTIFS('Coded Passages'!$B:$B,$A4,'Coded Passages'!$E:$E,$B4,'Coded Passages'!$H:$H,G$2) -> 0 | H4: =COUNTIFS('Coded Passages'!$B:$B,$A4,'Coded Passages'!$E:$E,$B4,'Coded Passages'!$H:$H,H$2) -> 1 | I4: =COUNTIFS('Coded Passages'!$B:$B,$A4,'Coded Passages'!$E:$E,$B4,'Coded Passages'!$H:$H,I$2) -> 0 | J4: =COUNTIFS('Coded Passages'!$B:$B,$A4,'Coded Passages'!$E:$E,$B4,'Coded Passages'!$H:$H,J$2) -> 0 | ... FO4: =COUNTIFS('Coded Passages'!$B:$B,$A4,'Coded Passages'!$E:$E,$B4,'Coded Passages'!$H:$H,FO$2) -> 7 | FP4: =SUM(C4:FO4) -> 102
A5: D1.1 | B5: Anti-State / Anti-Bureaucratic | C5: =COUNTIFS('Coded Passages'!$B:$B,$A5,'Coded Passages'!$E:$E,$B5,'Coded Passages'!$H:$H,C$2) -> 0 | D5: =COUNTIFS('Coded Passages'!$B:$B,$A5,'Coded Passages'!$E:$E,$B5,'Coded Passages'!$H:$H,D$2) -> 1 | E5: =COUNTIFS('Coded Passages'!$B:$B,$A5,'Coded Passages'!$E:$E,$B5,'Coded Passages'!$H:$H,E$2) -> 2 | F5: =COUNTIFS('Coded Passages'!$B:$B,$A5,'Coded Passages'!$E:$E,$B5,'Coded Passages'!$H:$H,F$2) -> 1 | G5: =COUNTIFS('Coded Passages'!$B:$B,$A5,'Coded Passages'!$E:$E,$B5,'Coded Passages'!$H:$H,G$2) -> 1 | H5: =COUNTIFS('Coded Passages'!$B:$B,$A5,'Coded Passages'!$E:$E,$B5,'Coded Passages'!$H:$H,H$2) -> 0 | I5: =COUNTIFS('Coded Passages'!$B:$B,$A5,'Coded Passages'!$E:$E,$B5,'Coded Passages'!$H:$H,I$2) -> 0 | J5: =COUNTIFS('Coded Passages'!$B:$B,$A5,'Coded Passages'!$E:$E,$B5,'Coded Passages'!$H:$H,J$2) -> 1 | ... FO5: =COUNTIFS('Coded Passages'!$B:$B,$A5,'Coded Passages'!$E:$E,$B5,'Coded Passages'!$H:$H,FO$2) -> 2 | FP5: =SUM(C5:FO5) -> 93
A6: D1.1 | B6: Delegitimization of Regulation | C6: =COUNTIFS('Coded Passages'!$B:$B,$A6,'Coded Passages'!$E:$E,$B6,'Coded Passages'!$H:$H,C$2) -> 0 | D6: =COUNTIFS('Coded Passages'!$B:$B,$A6,'Coded Passages'!$E:$E,$B6,'Coded Passages'!$H:$H,D$2) -> 0 | E6: =COUNTIFS('Coded Passages'!$B:$B,$A6,'Coded Passages'!$E:$E,$B6,'Coded Passages'!$H:$H,E$2) -> 2 | F6: =COUNTIFS('Coded Passages'!$B:$B,$A6,'Coded Passages'!$E:$E,$B6,'Coded Passages'!$H:$H,F$2) -> 0 | G6: =COUNTIFS('Coded Passages'!$B:$B,$A6,'Coded Passages'!$E:$E,$B6,'Coded Passages'!$H:$H,G$2) -> 6 | H6: =COUNTIFS('Coded Passages'!$B:$B,$A6,'Coded Passages'!$E:$E,$B6,'Coded Passages'!$H:$H,H$2) -> 1 | I6: =COUNTIFS('Coded Passages'!$B:$B,$A6,'Coded Passages'!$E:$E,$B6,'Coded Passages'!$H:$H,I$2) -> 1 | J6: =COUNTIFS('Coded Passages'!$B:$B,$A6,'Coded Passages'!$E:$E,$B6,'Coded Passages'!$H:$H,J$2) -> 0 | ... FO6: =COUNTIFS('Coded Passages'!$B:$B,$A6,'Coded Passages'!$E:$E,$B6,'Coded Passages'!$H:$H,FO$2) -> 6 | FP6: =SUM(C6:FO6) -> 85
A7: D1.3 | B7: Woke Bundling | C7: =COUNTIFS('Coded Passages'!$B:$B,$A7,'Coded Passages'!$E:$E,$B7,'Coded Passages'!$H:$H,C$2) -> 0 | D7: =COUNTIFS('Coded Passages'!$B:$B,$A7,'Coded Passages'!$E:$E,$B7,'Coded Passages'!$H:$H,D$2) -> 0 | E7: =COUNTIFS('Coded Passages'!$B:$B,$A7,'Coded Passages'!$E:$E,$B7,'Coded Passages'!$H:$H,E$2) -> 0 | F7: =COUNTIFS('Coded Passages'!$B:$B,$A7,'Coded Passages'!$E:$E,$B7,'Coded Passages'!$H:$H,F$2) -> 0 | G7: =COUNTIFS('Coded Passages'!$B:$B,$A7,'Coded Passages'!$E:$E,$B7,'Coded Passages'!$H:$H,G$2) -> 1 | H7: =COUNTIFS('Coded Passages'!$B:$B,$A7,'Coded Passages'!$E:$E,$B7,'Coded Passages'!$H:$H,H$2) -> 1 | I7: =COUNTIFS('Coded Passages'!$B:$B,$A7,'Coded Passages'!$E:$E,$B7,'Coded Passages'!$H:$H,I$2) -> 0 | J7: =COUNTIFS('Coded Passages'!$B:$B,$A7,'Coded Passages'!$E:$E,$B7,'Coded Passages'!$H:$H,J$2) -> 0 | ... FO7: =COUNTIFS('Coded Passages'!$B:$B,$A7,'Coded Passages'!$E:$E,$B7,'Coded Passages'!$H:$H,FO$2) -> 0 | FP7: =SUM(C7:FO7) -> 41
A8: D1.1 | B8: Market Primacy | C8: =COUNTIFS('Coded Passages'!$B:$B,$A8,'Coded Passages'!$E:$E,$B8,'Coded Passages'!$H:$H,C$2) -> 0 | D8: =COUNTIFS('Coded Passages'!$B:$B,$A8,'Coded Passages'!$E:$E,$B8,'Coded Passages'!$H:$H,D$2) -> 1 | E8: =COUNTIFS('Coded Passages'!$B:$B,$A8,'Coded Passages'!$E:$E,$B8,'Coded Passages'!$H:$H,E$2) -> 0 | F8: =COUNTIFS('Coded Passages'!$B:$B,$A8,'Coded Passages'!$E:$E,$B8,'Coded Passages'!$H:$H,F$2) -> 0 | G8: =COUNTIFS('Coded Passages'!$B:$B,$A8,'Coded Passages'!$E:$E,$B8,'Coded Passages'!$H:$H,G$2) -> 3 | H8: =COUNTIFS('Coded Passages'!$B:$B,$A8,'Coded Passages'!$E:$E,$B8,'Coded Passages'!$H:$H,H$2) -> 1 | I8: =COUNTIFS('Coded Passages'!$B:$B,$A8,'Coded Passages'!$E:$E,$B8,'Coded Passages'!$H:$H,I$2) -> 0 | J8: =COUNTIFS('Coded Passages'!$B:$B,$A8,'Coded Passages'!$E:$E,$B8,'Coded Passages'!$H:$H,J$2) -> 0 | ... FO8: =COUNTIFS('Coded Passages'!$B:$B,$A8,'Coded Passages'!$E:$E,$B8,'Coded Passages'!$H:$H,FO$2) -> 1 | FP8: =SUM(C8:FO8) -> 35
A9: D1.2 | B9: Attack on Experts & Technocrats | C9: =COUNTIFS('Coded Passages'!$B:$B,$A9,'Coded Passages'!$E:$E,$B9,'Coded Passages'!$H:$H,C$2) -> 1 | D9: =COUNTIFS('Coded Passages'!$B:$B,$A9,'Coded Passages'!$E:$E,$B9,'Coded Passages'!$H:$H,D$2) -> 0 | E9: =COUNTIFS('Coded Passages'!$B:$B,$A9,'Coded Passages'!$E:$E,$B9,'Coded Passages'!$H:$H,E$2) -> 0 | F9: =COUNTIFS('Coded Passages'!$B:$B,$A9,'Coded Passages'!$E:$E,$B9,'Coded Passages'!$H:$H,F$2) -> 0 | G9: =COUNTIFS('Coded Passages'!$B:$B,$A9,'Coded Passages'!$E:$E,$B9,'Coded Passages'!$H:$H,G$2) -> 1 | H9: =COUNTIFS('Coded Passages'!$B:$B,$A9,'Coded Passages'!$E:$E,$B9,'Coded Passages'!$H:$H,H$2) -> 0 | I9: =COUNTIFS('Coded Passages'!$B:$B,$A9,'Coded Passages'!$E:$E,$B9,'Coded Passages'!$H:$H,I$2) -> 0 | J9: =COUNTIFS('Coded Passages'!$B:$B,$A9,'Coded Passages'!$E:$E,$B9,'Coded Passages'!$H:$H,J$2) -> 0 | ... FO9: =COUNTIFS('Coded Passages'!$B:$B,$A9,'Coded Passages'!$E:$E,$B9,'Coded Passages'!$H:$H,FO$2) -> 0 | FP9: =SUM(C9:FO9) -> 32
A10: D1.3 | B10: Civilizational Defense | C10: =COUNTIFS('Coded Passages'!$B:$B,$A10,'Coded Passages'!$E:$E,$B10,'Coded Passages'!$H:$H,C$2) -> 0 | D10: =COUNTIFS('Coded Passages'!$B:$B,$A10,'Coded Passages'!$E:$E,$B10,'Coded Passages'!$H:$H,D$2) -> 0 | E10: =COUNTIFS('Coded Passages'!$B:$B,$A10,'Coded Passages'!$E:$E,$B10,'Coded Passages'!$H:$H,E$2) -> 0 | F10: =COUNTIFS('Coded Passages'!$B:$B,$A10,'Coded Passages'!$E:$E,$B10,'Coded Passages'!$H:$H,F$2) -> 0 | G10: =COUNTIFS('Coded Passages'!$B:$B,$A10,'Coded Passages'!$E:$E,$B10,'Coded Passages'!$H:$H,G$2) -> 1 | H10: =COUNTIFS('Coded Passages'!$B:$B,$A10,'Coded Passages'!$E:$E,$B10,'Coded Passages'!$H:$H,H$2) -> 0 | I10: =COUNTIFS('Coded Passages'!$B:$B,$A10,'Coded Passages'!$E:$E,$B10,'Coded Passages'!$H:$H,I$2) -> 0 | J10: =COUNTIFS('Coded Passages'!$B:$B,$A10,'Coded Passages'!$E:$E,$B10,'Coded Passages'!$H:$H,J$2) -> 0 | ... FO10: =COUNTIFS('Coded Passages'!$B:$B,$A10,'Coded Passages'!$E:$E,$B10,'Coded Passages'!$H:$H,FO$2) -> 0 | FP10: =SUM(C10:FO10) -> 27
A11: D1.1 | B11: Sustainability as Ideological or Harmful | C11: =COUNTIFS('Coded Passages'!$B:$B,$A11,'Coded Passages'!$E:$E,$B11,'Coded Passages'!$H:$H,C$2) -> 1 | D11: =COUNTIFS('Coded Passages'!$B:$B,$A11,'Coded Passages'!$E:$E,$B11,'Coded Passages'!$H:$H,D$2) -> 0 | E11: =COUNTIFS('Coded Passages'!$B:$B,$A11,'Coded Passages'!$E:$E,$B11,'Coded Passages'!$H:$H,E$2) -> 0 | F11: =COUNTIFS('Coded Passages'!$B:$B,$A11,'Coded Passages'!$E:$E,$B11,'Coded Passages'!$H:$H,F$2) -> 0 | G11: =COUNTIFS('Coded Passages'!$B:$B,$A11,'Coded Passages'!$E:$E,$B11,'Coded Passages'!$H:$H,G$2) -> 0 | H11: =COUNTIFS('Coded Passages'!$B:$B,$A11,'Coded Passages'!$E:$E,$B11,'Coded Passages'!$H:$H,H$2) -> 0 | I11: =COUNTIFS('Coded Passages'!$B:$B,$A11,'Coded Passages'!$E:$E,$B11,'Coded Passages'!$H:$H,I$2) -> 0 | J11: =COUNTIFS('Coded Passages'!$B:$B,$A11,'Coded Passages'!$E:$E,$B11,'Coded Passages'!$H:$H,J$2) -> 0 | ... FO11: =COUNTIFS('Coded Passages'!$B:$B,$A11,'Coded Passages'!$E:$E,$B11,'Coded Passages'!$H:$H,FO$2) -> 0 | FP11: =SUM(C11:FO11) -> 24
A12: D1.1 | B12: Rejection of Multilateral Governance | C12: =COUNTIFS('Coded Passages'!$B:$B,$A12,'Coded Passages'!$E:$E,$B12,'Coded Passages'!$H:$H,C$2) -> 0 | D12: =COUNTIFS('Coded Passages'!$B:$B,$A12,'Coded Passages'!$E:$E,$B12,'Coded Passages'!$H:$H,D$2) -> 0 | E12: =COUNTIFS('Coded Passages'!$B:$B,$A12,'Coded Passages'!$E:$E,$B12,'Coded Passages'!$H:$H,E$2) -> 0 | F12: =COUNTIFS('Coded Passages'!$B:$B,$A12,'Coded Passages'!$E:$E,$B12,'Coded Passages'!$H:$H,F$2) -> 0 | G12: =COUNTIFS('Coded Passages'!$B:$B,$A12,'Coded Passages'!$E:$E,$B12,'Coded Passages'!$H:$H,G$2) -> 1 | H12: =COUNTIFS('Coded Passages'!$B:$B,$A12,'Coded Passages'!$E:$E,$B12,'Coded Passages'!$H:$H,H$2) -> 0 | I12: =COUNTIFS('Coded Passages'!$B:$B,$A12,'Coded Passages'!$E:$E,$B12,'Coded Passages'!$H:$H,I$2) -> 0 | J12: =COUNTIFS('Coded Passages'!$B:$B,$A12,'Coded Passages'!$E:$E,$B12,'Coded Passages'!$H:$H,J$2) -> 0 | ... FO12: =COUNTIFS('Coded Passages'!$B:$B,$A12,'Coded Passages'!$E:$E,$B12,'Coded Passages'!$H:$H,FO$2) -> 0 | FP12: =SUM(C12:FO12) -> 24
A13: D1.2 | B13: Attack on Universities & Research Institutions | C13: =COUNTIFS('Coded Passages'!$B:$B,$A13,'Coded Passages'!$E:$E,$B13,'Coded Passages'!$H:$H,C$2) -> 0 | D13: =COUNTIFS('Coded Passages'!$B:$B,$A13,'Coded Passages'!$E:$E,$B13,'Coded Passages'!$H:$H,D$2) -> 0 | E13: =COUNTIFS('Coded Passages'!$B:$B,$A13,'Coded Passages'!$E:$E,$B13,'Coded Passages'!$H:$H,E$2) -> 0 | F13: =COUNTIFS('Coded Passages'!$B:$B,$A13,'Coded Passages'!$E:$E,$B13,'Coded Passages'!$H:$H,F$2) -> 0 | G13: =COUNTIFS('Coded Passages'!$B:$B,$A13,'Coded Passages'!$E:$E,$B13,'Coded Passages'!$H:$H,G$2) -> 0 | H13: =COUNTIFS('Coded Passages'!$B:$B,$A13,'Coded Passages'!$E:$E,$B13,'Coded Passages'!$H:$H,H$2) -> 0 | I13: =COUNTIFS('Coded Passages'!$B:$B,$A13,'Coded Passages'!$E:$E,$B13,'Coded Passages'!$H:$H,I$2) -> 1 | J13: =COUNTIFS('Coded Passages'!$B:$B,$A13,'Coded Passages'!$E:$E,$B13,'Coded Passages'!$H:$H,J$2) -> 1 | ... FO13: =COUNTIFS('Coded Passages'!$B:$B,$A13,'Coded Passages'!$E:$E,$B13,'Coded Passages'!$H:$H,FO$2) -> 0 | FP13: =SUM(C13:FO13) -> 14
A14: D1.2 | B14: Pseudo-Science / Ideological Science | C14: =COUNTIFS('Coded Passages'!$B:$B,$A14,'Coded Passages'!$E:$E,$B14,'Coded Passages'!$H:$H,C$2) -> 0 | D14: =COUNTIFS('Coded Passages'!$B:$B,$A14,'Coded Passages'!$E:$E,$B14,'Coded Passages'!$H:$H,D$2) -> 0 | E14: =COUNTIFS('Coded Passages'!$B:$B,$A14,'Coded Passages'!$E:$E,$B14,'Coded Passages'!$H:$H,E$2) -> 0 | F14: =COUNTIFS('Coded Passages'!$B:$B,$A14,'Coded Passages'!$E:$E,$B14,'Coded Passages'!$H:$H,F$2) -> 0 | G14: =COUNTIFS('Coded Passages'!$B:$B,$A14,'Coded Passages'!$E:$E,$B14,'Coded Passages'!$H:$H,G$2) -> 2 | H14: =COUNTIFS('Coded Passages'!$B:$B,$A14,'Coded Passages'!$E:$E,$B14,'Coded Passages'!$H:$H,H$2) -> 0 | I14: =COUNTIFS('Coded Passages'!$B:$B,$A14,'Coded Passages'!$E:$E,$B14,'Coded Passages'!$H:$H,I$2) -> 0 | J14: =COUNTIFS('Coded Passages'!$B:$B,$A14,'Coded Passages'!$E:$E,$B14,'Coded Passages'!$H:$H,J$2) -> 0 | ... FO14: =COUNTIFS('Coded Passages'!$B:$B,$A14,'Coded Passages'!$E:$E,$B14,'Coded Passages'!$H:$H,FO$2) -> 0 | FP14: =SUM(C14:FO14) -> 10
... A16: D1.2 | B16: Selective Empiricism | C16: =COUNTIFS('Coded Passages'!$B:$B,$A16,'Coded Passages'!$E:$E,$B16,'Coded Passages'!$H:$H,C$2) -> 0 | D16: =COUNTIFS('Coded Passages'!$B:$B,$A16,'Coded Passages'!$E:$E,$B16,'Coded Passages'!$H:$H,D$2) -> 0 | E16: =COUNTIFS('Coded Passages'!$B:$B,$A16,'Coded Passages'!$E:$E,$B16,'Coded Passages'!$H:$H,E$2) -> 0 | F16: =COUNTIFS('Coded Passages'!$B:$B,$A16,'Coded Passages'!$E:$E,$B16,'Coded Passages'!$H:$H,F$2) -> 0 | G16: =COUNTIFS('Coded Passages'!$B:$B,$A16,'Coded Passages'!$E:$E,$B16,'Coded Passages'!$H:$H,G$2) -> 1 | H16: =COUNTIFS('Coded Passages'!$B:$B,$A16,'Coded Passages'!$E:$E,$B16,'Coded Passages'!$H:$H,H$2) -> 0 | I16: =COUNTIFS('Coded Passages'!$B:$B,$A16,'Coded Passages'!$E:$E,$B16,'Coded Passages'!$H:$H,I$2) -> 0 | J16: =COUNTIFS('Coded Passages'!$B:$B,$A16,'Coded Passages'!$E:$E,$B16,'Coded Passages'!$H:$H,J$2) -> 0 | ... FO16: =COUNTIFS('Coded Passages'!$B:$B,$A16,'Coded Passages'!$E:$E,$B16,'Coded Passages'!$H:$H,FO$2) -> 0 | FP16: =SUM(C16:FO16) -> 3
A17: TOTAL | B17: All Sub-codes | C17: =SUM(C3:C16) -> 3 | D17: =SUM(D3:D16) -> 5 | E17: =SUM(E3:E16) -> 7 | F17: =SUM(F3:F16) -> 3 | G17: =SUM(G3:G16) -> 19 | H17: =SUM(H3:H16) -> 6 | I17: =SUM(I3:I16) -> 3 | J17: =SUM(J3:J16) -> 2 | ... FP17: =SUM(FP3:FP16) -> 613

Sheet Speech Overview
A1: Speech | B1: Date | C1: Venue | D1: Type | E1: Venue Group | F1: Scope | G1: D1.1 | H1: D1.2 | I1: D1.3 | J1: Total | K1: to manually check
A2: Madrid Economic Forum 2026 | B2: 2026-03-14 | C2: Madrid, España | D2: Foro Economico | E2: Economic & Business Forums | F2: International | G2: =COUNTIFS('Coded Passages'!$H:$H,$A2,'Coded Passages'!$B:$B,"D1.1") -> 12 | H2: =COUNTIFS('Coded Passages'!$H:$H,$A2,'Coded Passages'!$B:$B,"D1.2") -> 1 | I2: =COUNTIFS('Coded Passages'!$H:$H,$A2,'Coded Passages'!$B:$B,"D1.3") -> 8 | J2: =G2+H2+I2 -> 21 | K2: juani
A3: 54A Reunion Anual Del Foro Economico Mundial (Davos) | B3: 2024-01-17 | C3: Davos, Suiza | D3: Foro Economico | E3: Economic & Business Forums | F3: International | G3: =COUNTIFS('Coded Passages'!$H:$H,$A3,'Coded Passages'!$B:$B,"D1.1") -> 13 | H3: =COUNTIFS('Coded Passages'!$H:$H,$A3,'Coded Passages'!$B:$B,"D1.2") -> 4 | I3: =COUNTIFS('Coded Passages'!$H:$H,$A3,'Coded Passages'!$B:$B,"D1.3") -> 2 | J3: =G3+H3+I3 -> 19 | K3: eli
A4: Cierre De La Expo Efi 2026 | B4: 2026-04-29 | C4: Buenos Aires (C. De Convenciones) | D4: Foro Economico | E4: Economic & Business Forums | F4: National | G4: =COUNTIFS('Coded Passages'!$H:$H,$A4,'Coded Passages'!$B:$B,"D1.1") -> 10 | H4: =COUNTIFS('Coded Passages'!$H:$H,$A4,'Coded Passages'!$B:$B,"D1.2") -> 0 | I4: =COUNTIFS('Coded Passages'!$H:$H,$A4,'Coded Passages'!$B:$B,"D1.3") -> 7 | J4: =G4+H4+I4 -> 17 | K4: german
A5: 79 Asamblea General De La Onu – Debate General | B5: 2024-09-24 | C5: Nueva York, Ee.Uu. | D5: Cumbre Internacional | E5: International & Diplomatic | F5: International | G5: =COUNTIFS('Coded Passages'!$H:$H,$A5,'Coded Passages'!$B:$B,"D1.1") -> 8 | H5: =COUNTIFS('Coded Passages'!$H:$H,$A5,'Coded Passages'!$B:$B,"D1.2") -> 1 | I5: =COUNTIFS('Coded Passages'!$H:$H,$A5,'Coded Passages'!$B:$B,"D1.3") -> 4 | J5: =G5+H5+I5 -> 13 | K5: juani
A6: Palabras Ante Inversores De La Cpac | B6: 2024-11-15 | C6: Mar-A-Lago, Ee.Uu. | D6: Evento Ideologico/Politico | E6: Ideological & Political Events | F6: International | G6: =COUNTIFS('Coded Passages'!$H:$H,$A6,'Coded Passages'!$B:$B,"D1.1") -> 4 | H6: =COUNTIFS('Coded Passages'!$H:$H,$A6,'Coded Passages'!$B:$B,"D1.2") -> 0 | I6: =COUNTIFS('Coded Passages'!$H:$H,$A6,'Coded Passages'!$B:$B,"D1.3") -> 6 | J6: =G6+H6+I6 -> 10 | K6: eli
A7: 80 Asamblea General De La Onu | B7: 2025-09-24 | C7: Nueva York, Ee.Uu. | D7: Cumbre Internacional | E7: International & Diplomatic | F7: International | G7: =COUNTIFS('Coded Passages'!$H:$H,$A7,'Coded Passages'!$B:$B,"D1.1") -> 9 | H7: =COUNTIFS('Coded Passages'!$H:$H,$A7,'Coded Passages'!$B:$B,"D1.2") -> 0 | I7: =COUNTIFS('Coded Passages'!$H:$H,$A7,'Coded Passages'!$B:$B,"D1.3") -> 1 | J7: =G7+H7+I7 -> 10 | K7: german
A8: Clase Magistral En La Universidad Hebrea De Jerusalen | B8: 2025-06-12 | C8: Jerusalen, Israel | D8: Clase Magistral / Universidad | E8: Awards, Academic & Think Tanks | F8: International | G8: =COUNTIFS('Coded Passages'!$H:$H,$A8,'Coded Passages'!$B:$B,"D1.1") -> 9 | H8: =COUNTIFS('Coded Passages'!$H:$H,$A8,'Coded Passages'!$B:$B,"D1.2") -> 0 | I8: =COUNTIFS('Coded Passages'!$H:$H,$A8,'Coded Passages'!$B:$B,"D1.3") -> 0 | J8: =G8+H8+I8 -> 9 | K8: juani
A9: Apertura Del 144 Periodo De Sesiones Ordinarias | B9: 2026-03-01 | C9: Buenos Aires (Congreso) | D9: Acto Institucional | E9: State & Institutional Acts | F9: National | G9: =COUNTIFS('Coded Passages'!$H:$H,$A9,'Coded Passages'!$B:$B,"D1.1") -> 6 | H9: =COUNTIFS('Coded Passages'!$H:$H,$A9,'Coded Passages'!$B:$B,"D1.2") -> 0 | I9: =COUNTIFS('Coded Passages'!$H:$H,$A9,'Coded Passages'!$B:$B,"D1.3") -> 3 | J9: =G9+H9+I9 -> 9 | K9: eli
A10: Dia De La Industria – Union Industrial Argentina | B10: 2024-09-02 | C10: Buenos Aires (Uia) | D10: Sectorial | E10: Economic & Business Forums | F10: National | G10: =COUNTIFS('Coded Passages'!$H:$H,$A10,'Coded Passages'!$B:$B,"D1.1") -> 6 | H10: =COUNTIFS('Coded Passages'!$H:$H,$A10,'Coded Passages'!$B:$B,"D1.2") -> 1 | I10: =COUNTIFS('Coded Passages'!$H:$H,$A10,'Coded Passages'!$B:$B,"D1.3") -> 1 | J10: =G10+H10+I10 -> 8 | K10: german
A11: Tech Forum Argentina 2024 | B11: 2024-10-19 | C11: Buenos Aires (Hotel Libertador) | D11: Empresa | E11: Economic & Business Forums | F11: National | G11: =COUNTIFS('Coded Passages'!$H:$H,$A11,'Coded Passages'!$B:$B,"D1.1") -> 3 | H11: =COUNTIFS('Coded Passages'!$H:$H,$A11,'Coded Passages'!$B:$B,"D1.2") -> 3 | I11: =COUNTIFS('Coded Passages'!$H:$H,$A11,'Coded Passages'!$B:$B,"D1.3") -> 2 | J11: =G11+H11+I11 -> 8 | K11: juani
A12: Foro Economico Mundial De Davos 2025 | B12: 2025-01-23 | C12: Davos, Suiza | D12: Foro Economico | E12: Economic & Business Forums | F12: International | G12: =COUNTIFS('Coded Passages'!$H:$H,$A12,'Coded Passages'!$B:$B,"D1.1") -> 3 | H12: =COUNTIFS('Coded Passages'!$H:$H,$A12,'Coded Passages'!$B:$B,"D1.2") -> 3 | I12: =COUNTIFS('Coded Passages'!$H:$H,$A12,'Coded Passages'!$B:$B,"D1.3") -> 2 | J12: =G12+H12+I12 -> 8 | K12: eli
A13: La Derecha Fest | B13: 2025-07-22 | C13: Cordoba | D13: Evento Ideologico/Politico | E13: Ideological & Political Events | F13: National | G13: =COUNTIFS('Coded Passages'!$H:$H,$A13,'Coded Passages'!$B:$B,"D1.1") -> 4 | H13: =COUNTIFS('Coded Passages'!$H:$H,$A13,'Coded Passages'!$B:$B,"D1.2") -> 1 | I13: =COUNTIFS('Coded Passages'!$H:$H,$A13,'Coded Passages'!$B:$B,"D1.3") -> 3 | J13: =G13+H13+I13 -> 8 | K13: german
A14: Anuncios Por Cadena Nacional (Dnu/Desregulacion) | B14: 2023-12-20 | C14: Buenos Aires (Salon Blanco) | D14: Cadena Nacional | E14: State & Institutional Acts | F14: National | G14: =COUNTIFS('Coded Passages'!$H:$H,$A14,'Coded Passages'!$B:$B,"D1.1") -> 6 | H14: =COUNTIFS('Coded Passages'!$H:$H,$A14,'Coded Passages'!$B:$B,"D1.2") -> 0 | I14: =COUNTIFS('Coded Passages'!$H:$H,$A14,'Coded Passages'!$B:$B,"D1.3") -> 1 | J14: =G14+H14+I14 -> 7
A15: Acto De Vox "Viva 24" | B15: 2024-05-19 | C15: Madrid, España (Vistalegre) | D15: Evento Ideologico/Politico | E15: Ideological & Political Events | F15: International | G15: =COUNTIFS('Coded Passages'!$H:$H,$A15,'Coded Passages'!$B:$B,"D1.1") -> 4 | H15: =COUNTIFS('Coded Passages'!$H:$H,$A15,'Coded Passages'!$B:$B,"D1.2") -> 0 | I15: =COUNTIFS('Coded Passages'!$H:$H,$A15,'Coded Passages'!$B:$B,"D1.3") -> 3 | J15: =G15+H15+I15 -> 7
A16: Foro Madrid – Edicion Rio De La Plata | B16: 2024-09-05 | C16: Buenos Aires (Palacio Libertad) | D16: Evento Ideologico/Politico | E16: Ideological & Political Events | F16: National | G16: =COUNTIFS('Coded Passages'!$H:$H,$A16,'Coded Passages'!$B:$B,"D1.1") -> 3 | H16: =COUNTIFS('Coded Passages'!$H:$H,$A16,'Coded Passages'!$B:$B,"D1.2") -> 2 | I16: =COUNTIFS('Coded Passages'!$H:$H,$A16,'Coded Passages'!$B:$B,"D1.3") -> 2 | J16: =G16+H16+I16 -> 7
A17: Cena De La Fundacion Faro | B17: 2024-11-13 | C17: Buenos Aires | D17: Fundacion / Think Tank | E17: Awards, Academic & Think Tanks | F17: National | G17: =COUNTIFS('Coded Passages'!$H:$H,$A17,'Coded Passages'!$B:$B,"D1.1") -> 3 | H17: =COUNTIFS('Coded Passages'!$H:$H,$A17,'Coded Passages'!$B:$B,"D1.2") -> 2 | I17: =COUNTIFS('Coded Passages'!$H:$H,$A17,'Coded Passages'!$B:$B,"D1.3") -> 2 | J17: =G17+H17+I17 -> 7
A18: Conferencia Politica De Accion Conservadora (Cpac Argentina) | B18: 2024-12-05 | C18: Buenos Aires | D18: Evento Ideologico/Politico | E18: Ideological & Political Events | F18: National | G18: =COUNTIFS('Coded Passages'!$H:$H,$A18,'Coded Passages'!$B:$B,"D1.1") -> 4 | H18: =COUNTIFS('Coded Passages'!$H:$H,$A18,'Coded Passages'!$B:$B,"D1.2") -> 1 | I18: =COUNTIFS('Coded Passages'!$H:$H,$A18,'Coded Passages'!$B:$B,"D1.3") -> 2 | J18: =G18+H18+I18 -> 7
A19: Cpac Washington 2025 | B19: 2025-02-22 | C19: Washington D.C., Ee.Uu. | D19: Evento Ideologico/Politico | E19: Ideological & Political Events | F19: International | G19: =COUNTIFS('Coded Passages'!$H:$H,$A19,'Coded Passages'!$B:$B,"D1.1") -> 3 | H19: =COUNTIFS('Coded Passages'!$H:$H,$A19,'Coded Passages'!$B:$B,"D1.2") -> 2 | I19: =COUNTIFS('Coded Passages'!$H:$H,$A19,'Coded Passages'!$B:$B,"D1.3") -> 2 | J19: =G19+H19+I19 -> 7
A20: Apertura Del 143 Periodo De Sesiones Ordinarias | B20: 2025-03-01 | C20: Buenos Aires (Congreso) | D20: Acto Institucional | E20: State & Institutional Acts | F20: National | G20: =COUNTIFS('Coded Passages'!$H:$H,$A20,'Coded Passages'!$B:$B,"D1.1") -> 5 | H20: =COUNTIFS('Coded Passages'!$H:$H,$A20,'Coded Passages'!$B:$B,"D1.2") -> 0 | I20: =COUNTIFS('Coded Passages'!$H:$H,$A20,'Coded Passages'!$B:$B,"D1.3") -> 2 | J20: =G20+H20+I20 -> 7
A21: Bolsa De Comercio De Cordoba | B21: 2025-09-19 | C21: Cordoba | D21: Bolsa / Camara De Comercio | E21: Economic & Business Forums | F21: National | G21: =COUNTIFS('Coded Passages'!$H:$H,$A21,'Coded Passages'!$B:$B,"D1.1") -> 5 | H21: =COUNTIFS('Coded Passages'!$H:$H,$A21,'Coded Passages'!$B:$B,"D1.2") -> 0 | I21: =COUNTIFS('Coded Passages'!$H:$H,$A21,'Coded Passages'!$B:$B,"D1.3") -> 2 | J21: =G21+H21+I21 -> 7
A22: Cena De Fin De Año De La Fundacion Faro | B22: 2025-12-15 | C22: Buenos Aires | D22: Fundacion / Think Tank | E22: Awards, Academic & Think Tanks | F22: National | G22: =COUNTIFS('Coded Passages'!$H:$H,$A22,'Coded Passages'!$B:$B,"D1.1") -> 3 | H22: =COUNTIFS('Coded Passages'!$H:$H,$A22,'Coded Passages'!$B:$B,"D1.2") -> 2 | I22: =COUNTIFS('Coded Passages'!$H:$H,$A22,'Coded Passages'!$B:$B,"D1.3") -> 2 | J22: =G22+H22+I22 -> 7
A23: Gala Anual J100 De The Algemeiner | B23: 2026-03-10 | C23: Nueva York, Ee.Uu. | D23: Comunitario / Religioso | E23: Commemorative & Community | F23: International | G23: =COUNTIFS('Coded Passages'!$H:$H,$A23,'Coded Passages'!$B:$B,"D1.1") -> 6 | H23: =COUNTIFS('Coded Passages'!$H:$H,$A23,'Coded Passages'!$B:$B,"D1.2") -> 0 | I23: =COUNTIFS('Coded Passages'!$H:$H,$A23,'Coded Passages'!$B:$B,"D1.3") -> 1 | J23: =G23+H23+I23 -> 7
A24: Conferencia De Accion Politica Conservadora (Cpac) | B24: 2024-02-24 | C24: Washington D.C., Ee.Uu. | D24: Evento Ideologico/Politico | E24: Ideological & Political Events | F24: International | G24: =COUNTIFS('Coded Passages'!$H:$H,$A24,'Coded Passages'!$B:$B,"D1.1") -> 3 | H24: =COUNTIFS('Coded Passages'!$H:$H,$A24,'Coded Passages'!$B:$B,"D1.2") -> 1 | I24: =COUNTIFS('Coded Passages'!$H:$H,$A24,'Coded Passages'!$B:$B,"D1.3") -> 2 | J24: =G24+H24+I24 -> 6
A25: Clase Abierta En El Instituto Hoover (Universidad De Stanford) | B25: 2024-05-29 | C25: Stanford, California, Ee.Uu. | D25: Clase Magistral / Universidad | E25: Awards, Academic & Think Tanks | F25: International | G25: =COUNTIFS('Coded Passages'!$H:$H,$A25,'Coded Passages'!$B:$B,"D1.1") -> 5 | H25: =COUNTIFS('Coded Passages'!$H:$H,$A25,'Coded Passages'!$B:$B,"D1.2") -> 0 | I25: =COUNTIFS('Coded Passages'!$H:$H,$A25,'Coded Passages'!$B:$B,"D1.3") -> 1 | J25: =G25+H25+I25 -> 6
... A170: Palabras Junto A Isaac Herzog | B170: 2026-04-20 | C170: Israel | D170: Bilateral / Diplomatico | E170: International & Diplomatic | F170: International | G170: =COUNTIFS('Coded Passages'!$H:$H,$A170,'Coded Passages'!$B:$B,"D1.1") -> 0 | H170: =COUNTIFS('Coded Passages'!$H:$H,$A170,'Coded Passages'!$B:$B,"D1.2") -> 0 | I170: =COUNTIFS('Coded Passages'!$H:$H,$A170,'Coded Passages'!$B:$B,"D1.3") -> 1 | J170: =G170+H170+I170 -> 1
A171: TOTAL | G171: =SUM(G2:G170) -> 377 | H171: =SUM(H2:H170) -> 66 | I171: =SUM(I2:I170) -> 170 | J171: =SUM(J2:J170) -> 613

Sheet Freq — By Scope
A1: Code Frequency by Scope — values update automatically from 'Coded Passages'
A2: Dimension | B2: Dimension (Full) | C2: National | D2: International | E2: TOTAL
A3: D1.1 | B3: D1.1 — State Intervention & Governance | C3: =COUNTIFS('Coded Passages'!$B:$B,$A3,'Coded Passages'!$M:$M,"National") -> 240 | D3: =COUNTIFS('Coded Passages'!$B:$B,$A3,'Coded Passages'!$M:$M,"International") -> 137 | E3: =SUM(C3:D3) -> 377
A4: D1.2 | B4: D1.2 — Public Science & Expertise | C4: =COUNTIFS('Coded Passages'!$B:$B,$A4,'Coded Passages'!$M:$M,"National") -> 50 | D4: =COUNTIFS('Coded Passages'!$B:$B,$A4,'Coded Passages'!$M:$M,"International") -> 16 | E4: =SUM(C4:D4) -> 66
A5: D1.3 | B5: D1.3 — Cultural Backlash | C5: =COUNTIFS('Coded Passages'!$B:$B,$A5,'Coded Passages'!$M:$M,"National") -> 92 | D5: =COUNTIFS('Coded Passages'!$B:$B,$A5,'Coded Passages'!$M:$M,"International") -> 78 | E5: =SUM(C5:D5) -> 170
A6: TOTAL | B6: All Dimensions | C6: =SUM(C3:C5) -> 382 | D6: =SUM(D3:D5) -> 231 | E6: =SUM(E3:E5) -> 613
A28: Sub-code Detail by Scope
A29: Dim | B29: Sub-code | C29: National | D29: International | E29: TOTAL
A30: D1.1 | B30: Market Primacy | C30: =COUNTIFS('Coded Passages'!$B:$B,$A30,'Coded Passages'!$E:$E,$B30,'Coded Passages'!$M:$M,"National") -> 17 | D30: =COUNTIFS('Coded Passages'!$B:$B,$A30,'Coded Passages'!$E:$E,$B30,'Coded Passages'!$M:$M,"International") -> 18 | E30: =SUM(C30:D30) -> 35
A31: D1.1 | B31: Anti-State / Anti-Bureaucratic | C31: =COUNTIFS('Coded Passages'!$B:$B,$A31,'Coded Passages'!$E:$E,$B31,'Coded Passages'!$M:$M,"National") -> 63 | D31: =COUNTIFS('Coded Passages'!$B:$B,$A31,'Coded Passages'!$E:$E,$B31,'Coded Passages'!$M:$M,"International") -> 30 | E31: =SUM(C31:D31) -> 93
A32: D1.1 | B32: Anti-Casta (Elite Frame) | C32: =COUNTIFS('Coded Passages'!$B:$B,$A32,'Coded Passages'!$E:$E,$B32,'Coded Passages'!$M:$M,"National") -> 87 | D32: =COUNTIFS('Coded Passages'!$B:$B,$A32,'Coded Passages'!$E:$E,$B32,'Coded Passages'!$M:$M,"International") -> 29 | E32: =SUM(C32:D32) -> 116
A33: D1.1 | B33: Delegitimization of Regulation | C33: =COUNTIFS('Coded Passages'!$B:$B,$A33,'Coded Passages'!$E:$E,$B33,'Coded Passages'!$M:$M,"National") -> 53 | D33: =COUNTIFS('Coded Passages'!$B:$B,$A33,'Coded Passages'!$E:$E,$B33,'Coded Passages'!$M:$M,"International") -> 32 | E33: =SUM(C33:D33) -> 85
A34: D1.1 | B34: Sustainability as Ideological or Harmful | C34: =COUNTIFS('Coded Passages'!$B:$B,$A34,'Coded Passages'!$E:$E,$B34,'Coded Passages'!$M:$M,"National") -> 16 | D34: =COUNTIFS('Coded Passages'!$B:$B,$A34,'Coded Passages'!$E:$E,$B34,'Coded Passages'!$M:$M,"International") -> 8 | E34: =SUM(C34:D34) -> 24
A35: D1.1 | B35: Rejection of Multilateral Governance | C35: =COUNTIFS('Coded Passages'!$B:$B,$A35,'Coded Passages'!$E:$E,$B35,'Coded Passages'!$M:$M,"National") -> 4 | D35: =COUNTIFS('Coded Passages'!$B:$B,$A35,'Coded Passages'!$E:$E,$B35,'Coded Passages'!$M:$M,"International") -> 20 | E35: =SUM(C35:D35) -> 24
A36: D1.2 | B36: Attack on Universities & Research Institutions | C36: =COUNTIFS('Coded Passages'!$B:$B,$A36,'Coded Passages'!$E:$E,$B36,'Coded Passages'!$M:$M,"National") -> 11 | D36: =COUNTIFS('Coded Passages'!$B:$B,$A36,'Coded Passages'!$E:$E,$B36,'Coded Passages'!$M:$M,"International") -> 3 | E36: =SUM(C36:D36) -> 14
A37: D1.2 | B37: Attack on Experts & Technocrats | C37: =COUNTIFS('Coded Passages'!$B:$B,$A37,'Coded Passages'!$E:$E,$B37,'Coded Passages'!$M:$M,"National") -> 28 | D37: =COUNTIFS('Coded Passages'!$B:$B,$A37,'Coded Passages'!$E:$E,$B37,'Coded Passages'!$M:$M,"International") -> 4 | E37: =SUM(C37:D37) -> 32
A38: D1.2 | B38: Climate Skepticism or Dismissal | C38: =COUNTIFS('Coded Passages'!$B:$B,$A38,'Coded Passages'!$E:$E,$B38,'Coded Passages'!$M:$M,"National") -> 4 | D38: =COUNTIFS('Coded Passages'!$B:$B,$A38,'Coded Passages'!$E:$E,$B38,'Coded Passages'!$M:$M,"International") -> 3 | E38: =SUM(C38:D38) -> 7
A39: D1.2 | B39: Pseudo-Science / Ideological Science | C39: =COUNTIFS('Coded Passages'!$B:$B,$A39,'Coded Passages'!$E:$E,$B39,'Coded Passages'!$M:$M,"National") -> 5 | D39: =COUNTIFS('Coded Passages'!$B:$B,$A39,'Coded Passages'!$E:$E,$B39,'Coded Passages'!$M:$M,"International") -> 5 | E39: =SUM(C39:D39) -> 10
A40: D1.2 | B40: Selective Empiricism | C40: =COUNTIFS('Coded Passages'!$B:$B,$A40,'Coded Passages'!$E:$E,$B40,'Coded Passages'!$M:$M,"National") -> 2 | D40: =COUNTIFS('Coded Passages'!$B:$B,$A40,'Coded Passages'!$E:$E,$B40,'Coded Passages'!$M:$M,"International") -> 1 | E40: =SUM(C40:D40) -> 3
A41: D1.3 | B41: Woke Bundling | C41: =COUNTIFS('Coded Passages'!$B:$B,$A41,'Coded Passages'!$E:$E,$B41,'Coded Passages'!$M:$M,"National") -> 22 | D41: =COUNTIFS('Coded Passages'!$B:$B,$A41,'Coded Passages'!$E:$E,$B41,'Coded Passages'!$M:$M,"International") -> 19 | E41: =SUM(C41:D41) -> 41
... A43: D1.3 | B43: Civilizational Defense | C43: =COUNTIFS('Coded Passages'!$B:$B,$A43,'Coded Passages'!$E:$E,$B43,'Coded Passages'!$M:$M,"National") -> 5 | D43: =COUNTIFS('Coded Passages'!$B:$B,$A43,'Coded Passages'!$E:$E,$B43,'Coded Passages'!$M:$M,"International") -> 22 | E43: =SUM(C43:D43) -> 27
A44: TOTAL | B44: All Sub-codes | C44: =SUM(C30:C43) -> 382 | D44: =SUM(D30:D43) -> 231 | E44: =SUM(E30:E43) -> 613
A46: Sub-code Frequency Ranking — National vs. International
A47: National | B47: Sub-code | C47: Count | E47: International | F47: Sub-code | G47: Count
A48: D1.1 | B48: Anti-Casta (Elite Frame) | C48: 87 | E48: D1.3 | F48: Anti-Socialism / Anti-Collectivism | G48: 37
A49: D1.3 | B49: Anti-Socialism / Anti-Collectivism | C49: 65 | E49: D1.1 | F49: Delegitimization of Regulation | G49: 32
A50: D1.1 | B50: Anti-State / Anti-Bureaucratic | C50: 63 | E50: D1.1 | F50: Anti-State / Anti-Bureaucratic | G50: 30
A51: D1.1 | B51: Delegitimization of Regulation | C51: 53 | E51: D1.1 | F51: Anti-Casta (Elite Frame) | G51: 29
A52: D1.2 | B52: Attack on Experts & Technocrats | C52: 28 | E52: D1.3 | F52: Civilizational Defense | G52: 22
A53: D1.3 | B53: Woke Bundling | C53: 22 | E53: D1.1 | F53: Rejection of Multilateral Governance | G53: 20
A54: D1.1 | B54: Market Primacy | C54: 17 | E54: D1.3 | F54: Woke Bundling | G54: 19
A55: D1.1 | B55: Sustainability as Ideological or Harmful | C55: 16 | E55: D1.1 | F55: Market Primacy | G55: 18
